<?xml version="1.0" encoding="utf-8"?>
<!-- =================================================================================== -->
<!-- |    This document was autogenerated by xacro from popi_champ.xacro               | -->
<!-- |    EDITING THIS FILE BY HAND IS NOT RECOMMENDED                                 | -->
<!-- =================================================================================== -->
<!-- This URDF was automatically created by SolidWorks to URDF Exporter! Originally created by Stephen Brawner (brawner@gmail.com) 
     Commit Version: 1.5.1-0-g916b5db  Build Version: 1.5.7152.31018
     For more information, please see http://wiki.ros.org/sw_urdf_exporter -->
<robot name="popi">
  <!-- URDF -->
  <!-- damping : physical damping value of the joint [N*s / m] for prismatic joints, [N*m*s / rad] for revolute joints. -->
  <!-- friction : physical static friction value of the joint [N] for prismatic joints,[N/m] for revolute joints. -->
  <!-- lower : an attribute specifying the lower joint limit (radians for revolute joints, meters for prismatic joints). Omit if joint is continuous. -->
  <!-- upper : an attribute specifying the upper joint limit (radians for revolute joints, meters for prismatic joints). Omit if joint is continuous. -->
  <!-- effort : an attribute for enforcing the maximum joint effort (|applied effort| < |effort limit|). (N.m for revolute joints, N for prismatic joints) -->
  <!-- vel : an attribute for enforcing the maximum joint velocity. -->
  <!-- required ; taken into account in ODE physics engine -->
  <!-- SDF -->
  <!-- fdir : direction principale, dans le repere de collision du lien concerne, de la pyramide de frottement definie par mu1 et mu2. Si laisse par defaut, resultats imprevisibles. -->
  <!-- selfcollide : si sur 1, le lien peut entrer en collision avec les autres liens du modele ; deux liens connectes par un joint n'entreront pas en collision. -->
  <!-- kp : contact stiffness for rigid body contacts -->
  <!-- kd : damping for rigid body contacts -->
  <!-- NOTE : erp : error reduction parameter, par defaut erp = 0.2 | erp = ( dt * kp ) / ( dt * kp + kd ) -->
  <!-- NOTE : cfm : constraint force mixing parameter, par defaut cfm = 0 | cfm = 1 / ( dt * kp + kd ) -->
  <!-- mu1 : coefficient de friction mu, cone de friction approxime par une pyramide dont mu1 represente la premiere direction -->
  <!-- mu2 : coefficient de friction mu, cone de friction approxime par une pyramide dont mu2 represente la deuxieme direction -->
  <!-- maxVel : maximum contact correction velocity truncation term : lorsqu'il y a collision de deux entites, vitesse maximale du rebond. Important a set a faible valeur pour eviter un eclatement du modele -->
  <!-- minDepth : minimum allowable depth before contact correction impulse is applied -->
  <!-- default in ODE physics engine 0.0 -->
  <material name="black">
    <color rgba="0.0 0.0 0.0 1.0"/>
  </material>
  <material name="blue">
    <color rgba="0.0 0.0 0.8 1.0"/>
  </material>
  <material name="green">
    <color rgba="0.0 0.8 0.0 1.0"/>
  </material>
  <material name="grey">
    <color rgba="0.5 0.5 0.5 1.0"/>
  </material>
  <material name="darkgrey">
    <color rgba="0.2 0.2 0.2 1.0"/>
  </material>
  <material name="orange">
    <color rgba="1.0 0.423529411765 0.0392156862745 1.0"/>
  </material>
  <material name="brown">
    <color rgba="0.870588235294 0.811764705882 0.764705882353 1.0"/>
  </material>
  <material name="red">
    <color rgba="0.8 0.0 0.0 1.0"/>
  </material>
  <material name="white">
    <color rgba="1.0 1.0 1.0 1.0"/>
  </material>
  <gazebo reference="Bati">
    <material>Gazebo/Grey</material>
    <fdir1>1 0 0</fdir1>
    <self_collide>1</self_collide>
    <kp>1e+13</kp>
    <kd>1.0</kd>
    <mu1>1.0</mu1>
    <mu2>1.0</mu2>
    <maxVel>0.01</maxVel>
    <minDepth>0.0</minDepth>
  </gazebo>
  <gazebo reference="EpauleAVD">
    <material>Gazebo/Orange</material>
    <fdir1>0 1 0</fdir1>
    <self_collide>1</self_collide>
    <kp>1e+13</kp>
    <kd>1.0</kd>
    <mu1>1.0</mu1>
    <mu2>1.0</mu2>
    <maxVel>0.01</maxVel>
    <minDepth>0.0</minDepth>
  </gazebo>
  <gazebo reference="EpauleAVG">
    <material>Gazebo/Orange</material>
    <fdir1>0 1 0</fdir1>
    <self_collide>1</self_collide>
    <kp>1e+13</kp>
    <kd>1.0</kd>
    <mu1>1.0</mu1>
    <mu2>1.0</mu2>
    <maxVel>0.01</maxVel>
    <minDepth>0.0</minDepth>
  </gazebo>
  <gazebo reference="EpauleARD">
    <material>Gazebo/Orange</material>
    <fdir1>0 1 0</fdir1>
    <self_collide>1</self_collide>
    <kp>1e+13</kp>
    <kd>1.0</kd>
    <mu1>1.0</mu1>
    <mu2>1.0</mu2>
    <maxVel>0.01</maxVel>
    <minDepth>0.0</minDepth>
  </gazebo>
  <gazebo reference="EpauleARG">
    <material>Gazebo/Orange</material>
    <fdir1>0 1 0</fdir1>
    <self_collide>1</self_collide>
    <kp>1e+13</kp>
    <kd>1.0</kd>
    <mu1>1.0</mu1>
    <mu2>1.0</mu2>
    <maxVel>0.01</maxVel>
    <minDepth>0.0</minDepth>
  </gazebo>
  <gazebo reference="HJambeAVD">
    <material>Gazebo/DarkGrey</material>
    <fdir1>1 0 0</fdir1>
    <self_collide>1</self_collide>
    <kp>1e+13</kp>
    <kd>1.0</kd>
    <mu1>1.0</mu1>
    <mu2>1.0</mu2>
    <maxVel>0.01</maxVel>
    <minDepth>0.0</minDepth>
  </gazebo>
  <gazebo reference="HJambeAVG">
    <material>Gazebo/DarkGrey</material>
    <fdir1>1 0 0</fdir1>
    <self_collide>1</self_collide>
    <kp>1e+13</kp>
    <kd>1.0</kd>
    <mu1>1.0</mu1>
    <mu2>1.0</mu2>
    <maxVel>0.01</maxVel>
    <minDepth>0.0</minDepth>
  </gazebo>
  <gazebo reference="HJambeARD">
    <material>Gazebo/DarkGrey</material>
    <fdir1>1 0 0</fdir1>
    <self_collide>1</self_collide>
    <kp>1e+13</kp>
    <kd>1.0</kd>
    <mu1>1.0</mu1>
    <mu2>1.0</mu2>
    <maxVel>0.01</maxVel>
    <minDepth>0.0</minDepth>
  </gazebo>
  <gazebo reference="HJambeARG">
    <material>Gazebo/DarkGrey</material>
    <fdir1>1 0 0</fdir1>
    <self_collide>1</self_collide>
    <kp>1e+13</kp>
    <kd>1.0</kd>
    <mu1>1.0</mu1>
    <mu2>1.0</mu2>
    <maxVel>0.01</maxVel>
    <minDepth>0.0</minDepth>
  </gazebo>
  <gazebo reference="BJambeAVD">
    <material>Gazebo/White</material>
    <fdir1>1 0 0</fdir1>
    <self_collide>1</self_collide>
    <kp>1e+13</kp>
    <kd>1.0</kd>
    <mu1>1.0</mu1>
    <mu2>1.0</mu2>
    <maxVel>0.01</maxVel>
    <minDepth>0.02</minDepth>
  </gazebo>
  <gazebo reference="BJambeAVG">
    <material>Gazebo/White</material>
    <fdir1>1 0 0</fdir1>
    <self_collide>1</self_collide>
    <kp>1e+13</kp>
    <kd>1.0</kd>
    <mu1>1.0</mu1>
    <mu2>1.0</mu2>
    <maxVel>0.01</maxVel>
    <minDepth>0.02</minDepth>
  </gazebo>
  <gazebo reference="BJambeARD">
    <material>Gazebo/White</material>
    <fdir1>1 0 0</fdir1>
    <self_collide>1</self_collide>
    <kp>1e+13</kp>
    <kd>1.0</kd>
    <mu1>1.0</mu1>
    <mu2>1.0</mu2>
    <maxVel>0.01</maxVel>
    <minDepth>0.02</minDepth>
  </gazebo>
  <gazebo reference="BJambeARG">
    <material>Gazebo/White</material>
    <fdir1>1 0 0</fdir1>
    <self_collide>1</self_collide>
    <kp>1e+13</kp>
    <kd>1.0</kd>
    <mu1>1.0</mu1>
    <mu2>1.0</mu2>
    <maxVel>0.01</maxVel>
    <minDepth>0.02</minDepth>
  </gazebo>
  <gazebo reference="PiedAVD">
    <material>Gazebo/White</material>
    <fdir1>1 0 0</fdir1>
    <self_collide>1</self_collide>
    <kp>1e+13</kp>
    <kd>1</kd>
    <mu1>1.0</mu1>
    <mu2>1.0</mu2>
    <maxVel>0.01</maxVel>
    <minDepth>0.02</minDepth>
  </gazebo>
  <gazebo reference="PiedAVG">
    <material>Gazebo/White</material>
    <fdir1>1 0 0</fdir1>
    <self_collide>1</self_collide>
    <kp>1e+13</kp>
    <kd>1</kd>
    <mu1>1.0</mu1>
    <mu2>1.0</mu2>
    <maxVel>0.01</maxVel>
    <minDepth>0.02</minDepth>
  </gazebo>
  <gazebo reference="PiedARD">
    <material>Gazebo/White</material>
    <fdir1>1 0 0</fdir1>
    <self_collide>1</self_collide>
    <kp>1e+13</kp>
    <kd>1</kd>
    <mu1>1.0</mu1>
    <mu2>1.0</mu2>
    <maxVel>0.01</maxVel>
    <minDepth>0.02</minDepth>
  </gazebo>
  <gazebo reference="PiedARG">
    <material>Gazebo/White</material>
    <fdir1>1 0 0</fdir1>
    <self_collide>1</self_collide>
    <kp>1e+13</kp>
    <kd>1</kd>
    <mu1>1.0</mu1>
    <mu2>1.0</mu2>
    <maxVel>0.01</maxVel>
    <minDepth>0.02</minDepth>
  </gazebo>
  <!--**************************************************************************************-->
  <!--*************************************** CORPS ****************************************-->
  <!--**************************************************************************************-->
  <link name="Base_flottante">
    <visual>
      <origin rpy="0 0 0" xyz="0 0 0"/>
      <geometry>
        <box size="0.001 0.001 0.001"/>
      </geometry>
    </visual>
  </link>
  <joint name="base_flottante" type="fixed">
    <origin rpy="0 0 0" xyz="0 0 0"/>
    <parent link="Base_flottante"/>
    <child link="Bati"/>
  </joint>
  <link name="Bati">
    <inertial>
      <origin rpy="0 0 0" xyz="0 0 -0.03523"/>
      <mass value="22.934"/>
      <inertia ixx="0.38573" ixy="0" ixz="0" iyy="0.90692" iyz="0" izz="1.2277"/>
    </inertial>
    <visual>
      <origin rpy="0 0 0" xyz="0 0 0"/>
      <geometry>
        <mesh filename="package://popi_description/meshes/Bati.STL"/>
      </geometry>
      <material name="grey"/>
    </visual>
    <collision>
      <origin rpy="0 0 0" xyz="0 0 -0.035"/>
      <geometry>
        <box size="0.84 0.4 0.2"/>
      </geometry>
    </collision>
  </link>
  <!--**************************************************************************************-->
  <!--********************************* JAMBE AVANT-DROITE *********************************-->
  <!--**************************************************************************************-->
  <link name="EpauleAVD">
    <inertial>
      <origin rpy="0 0 0" xyz="-0.00137 0.04355 -0.00354"/>
      <mass value="6.775"/>
      <inertia ixx="0.0286" ixy="6E-05" ixz="-0.00018" iyy="0.01067" iyz="-0.00075" izz="0.02893"/>
    </inertial>
    <visual>
      <origin rpy="0 0 0" xyz="0 0 0"/>
      <geometry>
        <mesh filename="package://popi_description/meshes/EpauleAVD.STL"/>
      </geometry>
      <material name="orange"/>
    </visual>
    <collision>
      <origin rpy="0 0 0" xyz="0 0.075 0"/>
      <geometry>
        <box size="0.15 0.15 0.12"/>
      </geometry>
    </collision>
  </link>
  <link name="HJambeAVD">
    <inertial>
      <origin rpy="0 0 0" xyz="0.01743 0.00512 -0.11331"/>
      <mass value="4.955"/>
      <inertia ixx="0.00899" ixy="0.00215" ixz="0.00647" iyy="0.0605" iyz="-0.00043" izz="0.05703"/>
    </inertial>
    <visual>
      <origin rpy="0 -1.5708 0" xyz="0 0 0"/>
      <geometry>
        <mesh filename="package://popi_description/meshes/HJambeAVD.STL"/>
      </geometry>
      <material name="darkgrey"/>
    </visual>
    <collision>
      <origin rpy="0 0 0" xyz="0 0 -0.15"/>
      <geometry>
        <box size="0.1 0.1 -0.43"/>
      </geometry>
    </collision>
  </link>
  <link name="BJambeAVD">
    <inertial>
      <origin rpy="0 0 0" xyz="-0.012387 0 -0.11761"/>
      <mass value="0.49"/>
      <inertia ixx="0.000103" ixy="0.000000" ixz="-0.00019" iyy="0.006798" iyz="0" izz="0.006776"/>
    </inertial>
    <visual>
      <origin rpy="0 1.5708 0" xyz="0 0 0"/>
      <geometry>
        <mesh filename="package://popi_description/meshes/BJambeAVD.STL"/>
      </geometry>
      <material name="white"/>
    </visual>
    <collision>
      <origin rpy="0 0 0" xyz="0 0 -0.08"/>
      <geometry>
        <box size="0.05 0.05 -0.32"/>
      </geometry>
    </collision>
  </link>
  <link name="PiedAVD">
    <inertial>
      <origin rpy="0 0 0" xyz="0.0005 1.1348E-09 -1.2018E-09"/>
      <mass value="0.001"/>
      <inertia ixx="1.0417E-10" ixy="3.2086E-25" ixz="2.1003E-26" iyy="5.4167E-11" iyz="6.3205E-25" izz="5.4167E-11"/>
    </inertial>
    <visual>
      <origin rpy="0 0 0" xyz="0 0 0"/>
      <geometry>
        <mesh filename="package://popi_description/meshes/PiedAVD.STL"/>
      </geometry>
      <material name="white"/>
    </visual>
    <collision>
      <origin rpy="0 0 0" xyz="0 0 0.033"/>
      <geometry>
        <sphere radius="0.0335"/>
      </geometry>
    </collision>
  </link>
  <!--**************************************************************************************-->
  <!--********************************* JAMBE AVANT-GAUCHE *********************************-->
  <!--**************************************************************************************-->
  <link name="EpauleAVG">
    <inertial>
      <origin rpy="0 0 0" xyz="-0.00137 -0.04355 -0.00354"/>
      <mass value="6.775"/>
      <inertia ixx="0.02864" ixy="-6E-05" ixz="-0.00018" iyy="0.01067" iyz="0.00075" izz="0.02893"/>
    </inertial>
    <visual>
      <origin rpy="0 0 0" xyz="0 0 0"/>
      <geometry>
        <mesh filename="package://popi_description/meshes/EpauleAVG.STL"/>
      </geometry>
      <material name="orange"/>
    </visual>
    <collision>
      <origin rpy="0 0 0" xyz="0 -0.075 0"/>
      <geometry>
        <box size="0.15 0.15 0.12"/>
      </geometry>
    </collision>
  </link>
  <link name="HJambeAVG">
    <inertial>
      <origin rpy="0 -1.495 0" xyz="0.00901 -0.00555 -0.11389"/>
      <mass value="4.955"/>
      <inertia ixx="0.01032" ixy="-0.00226" ixz="0.01011" iyy="0.06056" iyz="0.00025" izz="0.05596"/>
    </inertial>
    <visual>
      <origin rpy="0 -1.495 0" xyz="0 0 0"/>
      <geometry>
        <mesh filename="package://popi_description/meshes/HJambeAVG.STL"/>
      </geometry>
      <material name="darkgrey"/>
    </visual>
    <collision>
      <origin rpy="0 0 0" xyz="0 0 -0.15"/>
      <geometry>
        <box size="0.1 0.1 -0.43"/>
      </geometry>
    </collision>
  </link>
  <link name="BJambeAVG">
    <inertial>
      <origin rpy="0 0 0" xyz="-0.012387 0 -0.11761"/>
      <mass value="0.49"/>
      <inertia ixx="0.000103" ixy="0.000000" ixz="-0.00019" iyy="0.006798" iyz="0" izz="0.006776"/>
    </inertial>
    <visual>
      <origin rpy="0 1.5708 0" xyz="0 0 0"/>
      <geometry>
        <mesh filename="package://popi_description/meshes/BJambeAVG.STL"/>
      </geometry>
      <material name="white"/>
    </visual>
    <collision>
      <origin rpy="0 0 0" xyz="0 0 -0.08"/>
      <geometry>
        <box size="0.05 0.05 -0.32"/>
      </geometry>
    </collision>
  </link>
  <link name="PiedAVG">
    <inertial>
      <origin rpy="0 0 0" xyz="0.0005 -3.5068E-06 -4.4931E-09"/>
      <mass value="0.001"/>
      <inertia ixx="1.0417E-10" ixy="4.4849E-25" ixz="1.454E-25" iyy="5.4167E-11" iyz="6.3205E-25" izz="5.4167E-11"/>
    </inertial>
    <visual>
      <origin rpy="0 0 0" xyz="0 0 0"/>
      <geometry>
        <mesh filename="package://popi_description/meshes/PiedAVG.STL"/>
      </geometry>
      <material name="white"/>
    </visual>
    <collision>
      <origin rpy="0 0 0" xyz="0 0 0.033"/>
      <geometry>
        <sphere radius="0.0335"/>
      </geometry>
    </collision>
  </link>
  <!--**************************************************************************************-->
  <!--******************************** JAMBE ARRIERE-DROITE ********************************-->
  <!--**************************************************************************************-->
  <link name="EpauleARD">
    <inertial>
      <origin rpy="0 0 0" xyz="0.00137 0.04355 -0.00354"/>
      <mass value="6.775"/>
      <inertia ixx="0.02864" ixy="-6E-05" ixz="1.8E-05" iyy="0.01067" iyz="-0.00075" izz="0.02893"/>
    </inertial>
    <visual>
      <origin rpy="0 0 0" xyz="0 0 0"/>
      <geometry>
        <mesh filename="package://popi_description/meshes/EpauleARD.STL"/>
      </geometry>
      <material name="orange"/>
    </visual>
    <collision>
      <origin rpy="0 0 0" xyz="0 0.075 0"/>
      <geometry>
        <box size="0.15 0.15 0.12"/>
      </geometry>
    </collision>
  </link>
  <link name="HJambeARD">
    <inertial>
      <origin rpy="0 0 0" xyz="0.01743 0.00512 -0.11331"/>
      <mass value="4.955"/>
      <inertia ixx="0.00899" ixy="0.00215" ixz="0.00647" iyy="0.0605" iyz="-0.00043" izz="0.05703"/>
    </inertial>
    <visual>
      <origin rpy="0 -1.5708 0" xyz="0 0 0"/>
      <geometry>
        <mesh filename="package://popi_description/meshes/HJambeARD.STL"/>
      </geometry>
      <material name="darkgrey"/>
    </visual>
    <collision>
      <origin rpy="0 0 0" xyz="0 0 -0.15"/>
      <geometry>
        <box size="0.1 0.1 -0.43"/>
      </geometry>
    </collision>
  </link>
  <link name="BJambeARD">
    <inertial>
      <origin rpy="0 0 0" xyz="-0.012387 0 -0.11761"/>
      <mass value="0.49"/>
      <inertia ixx="0.000103" ixy="0.000000" ixz="-0.00019" iyy="0.006798" iyz="0" izz="0.006776"/>
    </inertial>
    <visual>
      <origin rpy="0 1.5708 0" xyz="0 0 0"/>
      <geometry>
        <mesh filename="package://popi_description/meshes/BJambeARD.STL"/>
      </geometry>
      <material name="white"/>
    </visual>
    <collision>
      <origin rpy="0 0 0" xyz="0 0 -0.08"/>
      <geometry>
        <box size="0.05 0.05 -0.32"/>
      </geometry>
    </collision>
  </link>
  <link name="PiedARD">
    <inertial>
      <origin rpy="0 0 0" xyz="0.0005 -3.0378E-12 -8.2379E-14"/>
      <mass value="0.001"/>
      <inertia ixx="1.0417E-10" ixy="-3.7731E-26" ixz="-1.6964E-25" iyy="5.4167E-11" iyz="1.0234E-25" izz="5.4167E-11"/>
    </inertial>
    <visual>
      <origin rpy="0 0 0" xyz="0 0 0"/>
      <geometry>
        <mesh filename="package://popi_description/meshes/PiedARD.STL"/>
      </geometry>
      <material name="white"/>
    </visual>
    <collision>
      <origin rpy="0 0 0" xyz="0 0 0.033"/>
      <geometry>
        <sphere radius="0.0335"/>
      </geometry>
    </collision>
  </link>
  <!--**************************************************************************************-->
  <!--******************************** JAMBE ARRIERE-GAUCHE ********************************-->
  <!--**************************************************************************************-->
  <link name="EpauleARG">
    <inertial>
      <origin rpy="0 0 0" xyz="0.00137 -0.04355 -0.00354"/>
      <mass value="6.775"/>
      <inertia ixx="0.02864" ixy="6E-05" ixz="0.00018" iyy="0.01067" iyz="0.00075" izz="0.02893"/>
    </inertial>
    <visual>
      <origin rpy="0 0 0" xyz="0 0 0"/>
      <geometry>
        <mesh filename="package://popi_description/meshes/EpauleARG.STL"/>
      </geometry>
      <material name="orange"/>
    </visual>
    <collision>
      <origin rpy="0 0 0" xyz="0 -0.075 0"/>
      <geometry>
        <box size="0.15 0.15 0.12"/>
      </geometry>
    </collision>
  </link>
  <link name="HJambeARG">
    <inertial>
      <origin rpy="0 -1.495 0" xyz="0.00901 -0.00555 -0.11389"/>
      <mass value="4.955"/>
      <inertia ixx="0.01032" ixy="-0.00226" ixz="0.01011" iyy="0.06056" iyz="0.00025" izz="0.05596"/>
    </inertial>
    <visual>
      <origin rpy="0 -1.495 0" xyz="0 0 0"/>
      <geometry>
        <mesh filename="package://popi_description/meshes/HJambeARG.STL"/>
      </geometry>
      <material name="darkgrey"/>
    </visual>
    <collision>
      <origin rpy="0 0 0" xyz="0 0 -0.15"/>
      <geometry>
        <box size="0.1 0.1 -0.43"/>
      </geometry>
    </collision>
  </link>
  <link name="BJambeARG">
    <inertial>
      <origin rpy="0 0 0" xyz="-0.012387 0 -0.11761"/>
      <mass value="0.49"/>
      <inertia ixx="0.000103" ixy="0.000000" ixz="-0.00019" iyy="0.006798" iyz="0" izz="0.006776"/>
    </inertial>
    <visual>
      <origin rpy="0 1.5708 0" xyz="0 0 0"/>
      <geometry>
        <mesh filename="package://popi_description/meshes/BJambeARG.STL"/>
      </geometry>
      <material name="white"/>
    </visual>
    <collision>
      <origin rpy="0 0 0" xyz="0 0 -0.08"/>
      <geometry>
        <box size="0.05 0.05 -0.32"/>
      </geometry>
    </collision>
  </link>
  <link name="PiedARG">
    <inertial>
      <origin rpy="0 0 0" xyz="0.0005 -3.5073E-06 5.5511E-14"/>
      <mass value="0.001"/>
      <inertia ixx="1.0417E-10" ixy="6.1999E-25" ixz="-9.8551E-26" iyy="5.4167E-11" iyz="-1.1985E-25" izz="5.4167E-11"/>
    </inertial>
    <visual>
      <origin rpy="0 0 0" xyz="0 0 0"/>
      <geometry>
        <mesh filename="package://popi_description/meshes/PiedARG.STL"/>
      </geometry>
      <material name="white"/>
    </visual>
    <collision>
      <origin rpy="0 0 0" xyz="0 0 0.033"/>
      <geometry>
        <sphere radius="0.0335"/>
      </geometry>
    </collision>
  </link>
  <!--**************************************************************************************-->
  <!--********************************* JOINTS AVANT-DROITS ********************************-->
  <!--**************************************************************************************-->
  <joint name="aileAVD" type="revolute">
    <origin rpy="0 0 0" xyz="0.3305 -0.175 -0.051"/>
    <parent link="Bati"/>
    <child link="EpauleAVD"/>
    <axis xyz="1 0 0"/>
    <limit effort="120" lower="-0.4" upper="0.4" velocity="3.14159265359"/>
    <dynamics damping="0.1" friction="4.5"/>
  </joint>
  <joint name="epauleAVD" type="revolute">
    <origin rpy="0 0 0" xyz="0 -0.1077 0"/>
    <parent link="EpauleAVD"/>
    <child link="HJambeAVD"/>
    <axis xyz="0 1 0"/>
    <limit effort="122" lower="-1.5708" upper="1.5708" velocity="2.87"/>
    <dynamics damping="0.1" friction="7.5"/>
  </joint>
  <joint name="coudeAVD" type="revolute">
    <origin rpy="0 0 0" xyz="0.041509 0 -0.35192"/>
    <parent link="HJambeAVD"/>
    <child link="BJambeAVD"/>
    <axis xyz="0 1 0"/>
    <limit effort="110" lower="-0.26" upper="1.92" velocity="0.34"/>
    <dynamics damping="0.1" friction="5"/>
  </joint>
  <joint name="piedAVD" type="fixed">
    <origin rpy="0 0 0" xyz="-0.015 0 -0.29604"/>
    <parent link="BJambeAVD"/>
    <child link="PiedAVD"/>
    <axis xyz="0 0 0"/>
  </joint>
  <!--**************************************************************************************-->
  <!--******************************** JOINTS AVANT-GAUCHES ********************************-->
  <!--**************************************************************************************-->
  <joint name="aileAVG" type="revolute">
    <origin rpy="0 0 0" xyz="0.3305 0.175 -0.051"/>
    <parent link="Bati"/>
    <child link="EpauleAVG"/>
    <axis xyz="1 0 0"/>
    <limit effort="120" lower="-0.4" upper="0.4" velocity="3.14159265359"/>
    <dynamics damping="0.1" friction="4.5"/>
  </joint>
  <joint name="epauleAVG" type="revolute">
    <origin rpy="0 0 0" xyz="0 0.1077 0"/>
    <parent link="EpauleAVG"/>
    <child link="HJambeAVG"/>
    <axis xyz="0 1 0"/>
    <limit effort="122" lower="-1.5708" upper="1.5708" velocity="2.87"/>
    <dynamics damping="0.1" friction="7.5"/>
  </joint>
  <joint name="coudeAVG" type="revolute">
    <origin rpy="0 0 0" xyz="0.041509 0 -0.35192"/>
    <parent link="HJambeAVG"/>
    <child link="BJambeAVG"/>
    <axis xyz="0 1 0"/>
    <limit effort="110" lower="-0.26" upper="1.92" velocity="0.34"/>
    <dynamics damping="0.1" friction="5"/>
  </joint>
  <joint name="piedAVG" type="fixed">
    <origin rpy="0 0 0" xyz="-0.015 0 -0.29604"/>
    <parent link="BJambeAVG"/>
    <child link="PiedAVG"/>
    <axis xyz="0 0 0"/>
  </joint>
  <!--**************************************************************************************-->
  <!--******************************* JOINTS ARRIERE-DROITS ********************************-->
  <!--**************************************************************************************-->
  <joint name="aileARD" type="revolute">
    <origin rpy="0 0 0" xyz="-0.3305 -0.175 -0.051"/>
    <parent link="Bati"/>
    <child link="EpauleARD"/>
    <axis xyz="1 0 0"/>
    <limit effort="120" lower="-0.4" upper="0.4" velocity="3.14159265359"/>
    <dynamics damping="0.1" friction="4.5"/>
  </joint>
  <joint name="epauleARD" type="revolute">
    <origin rpy="0 0 0" xyz="0 -0.1077 0"/>
    <parent link="EpauleARD"/>
    <child link="HJambeARD"/>
    <axis xyz="0 1 0"/>
    <limit effort="122" lower="-1.5708" upper="1.5708" velocity="2.87"/>
    <dynamics damping="0.1" friction="7.5"/>
  </joint>
  <joint name="coudeARD" type="revolute">
    <origin rpy="0 0 0" xyz="0.041509 0 -0.35192"/>
    <parent link="HJambeARD"/>
    <child link="BJambeARD"/>
    <axis xyz="0 1 0"/>
    <limit effort="110" lower="-0.26" upper="1.92" velocity="0.34"/>
    <dynamics damping="0.1" friction="5"/>
  </joint>
  <joint name="piedARD" type="fixed">
    <origin rpy="0 0 0" xyz="-0.015 0 -0.29604"/>
    <parent link="BJambeARD"/>
    <child link="PiedARD"/>
    <axis xyz="0 0 0"/>
  </joint>
  <!--**************************************************************************************-->
  <!--****************************** JOINTS ARRIERE-GAUCHES ********************************-->
  <!--**************************************************************************************-->
  <joint name="aileARG" type="revolute">
    <origin rpy="0 0 0" xyz="-0.3305 0.175 -0.051"/>
    <parent link="Bati"/>
    <child link="EpauleARG"/>
    <axis xyz="1 0 0"/>
    <limit effort="120" lower="-0.4" upper="0.4" velocity="3.14159265359"/>
    <dynamics damping="0.1" friction="4.5"/>
  </joint>
  <joint name="epauleARG" type="revolute">
    <origin rpy="0 0 0" xyz="0 0.1077 0"/>
    <parent link="EpauleARG"/>
    <child link="HJambeARG"/>
    <axis xyz="0 1 0"/>
    <limit effort="122" lower="-1.5708" upper="1.5708" velocity="2.87"/>
    <dynamics damping="0.1" friction="7.5"/>
  </joint>
  <joint name="coudeARG" type="revolute">
    <origin rpy="0 0 0" xyz="0.041509 0 -0.35192"/>
    <parent link="HJambeARG"/>
    <child link="BJambeARG"/>
    <axis xyz="0 1 0"/>
    <limit effort="110" lower="-0.26" upper="1.92" velocity="0.34"/>
    <dynamics damping="0.1" friction="5"/>
  </joint>
  <joint name="piedARG" type="fixed">
    <origin rpy="0 0 0" xyz="-0.015 0 -0.29604"/>
    <parent link="BJambeARG"/>
    <child link="PiedARG"/>
    <axis xyz="0 0 0"/>
  </joint>
  <!--**************************************************************************************-->
  <!--********************************** PLUGINS GAZEBO ************************************-->
  <!--**************************************************************************************-->
  <gazebo>
    <plugin filename="libgazebo_ros_control.so" name="gazebo_ros_control">
      <legacyModeNS>true</legacyModeNS>
    </plugin>
  </gazebo>
  <!--**************************************************************************************-->
  <!--***************************** TRANSMISSIONS AVANT-DROITES ****************************-->
  <!--**************************************************************************************-->
  <transmission name="aileAVD_tran">
    <type>transmission_interface/SimpleTransmission</type>
    <joint name="aileAVD">
      <hardwareInterface>hardware_interface/EffortJointInterface</hardwareInterface>
    </joint>
    <actuator name="aileAVD_moteur">
      <mechanicalReduction>1</mechanicalReduction>
      <hardwareInterface>hardware_interface/EffortJointInterface</hardwareInterface>
    </actuator>
  </transmission>
  <transmission name="epauleAVD_tran">
    <type>transmission_interface/SimpleTransmission</type>
    <joint name="epauleAVD">
      <hardwareInterface>hardware_interface/EffortJointInterface</hardwareInterface>
    </joint>
    <actuator name="epauleAVD_moteur">
      <mechanicalReduction>1</mechanicalReduction>
      <hardwareInterface>hardware_interface/EffortJointInterface</hardwareInterface>
    </actuator>
  </transmission>
  <transmission name="coudeAVD_tran">
    <type>transmission_interface/SimpleTransmission</type>
    <joint name="coudeAVD">
      <hardwareInterface>hardware_interface/EffortJointInterface</hardwareInterface>
    </joint>
    <actuator name="coudeAVD_moteur">
      <mechanicalReduction>1</mechanicalReduction>
      <hardwareInterface>hardware_interface/EffortJointInterface</hardwareInterface>
    </actuator>
  </transmission>
  <!--**************************************************************************************-->
  <!--***************************** TRANSMISSIONS AVANT-GAUCHES ****************************-->
  <!--**************************************************************************************-->
  <transmission name="aileAVG_tran">
    <type>transmission_interface/SimpleTransmission</type>
    <joint name="aileAVG">
      <hardwareInterface>hardware_interface/EffortJointInterface</hardwareInterface>
    </joint>
    <actuator name="aileAVG_moteur">
      <mechanicalReduction>1</mechanicalReduction>
      <hardwareInterface>hardware_interface/EffortJointInterface</hardwareInterface>
    </actuator>
  </transmission>
  <transmission name="epauleAVG_tran">
    <type>transmission_interface/SimpleTransmission</type>
    <joint name="epauleAVG">
      <hardwareInterface>hardware_interface/EffortJointInterface</hardwareInterface>
    </joint>
    <actuator name="epauleAVG_moteur">
      <mechanicalReduction>1</mechanicalReduction>
      <hardwareInterface>hardware_interface/EffortJointInterface</hardwareInterface>
    </actuator>
  </transmission>
  <transmission name="coudeAVG_tran">
    <type>transmission_interface/SimpleTransmission</type>
    <joint name="coudeAVG">
      <hardwareInterface>hardware_interface/EffortJointInterface</hardwareInterface>
    </joint>
    <actuator name="coudeAVG_moteur">
      <mechanicalReduction>1</mechanicalReduction>
      <hardwareInterface>hardware_interface/EffortJointInterface</hardwareInterface>
    </actuator>
  </transmission>
  <!--**************************************************************************************-->
  <!--**************************** TRANSMISSIONS ARRIERE-DROITES ***************************-->
  <!--**************************************************************************************-->
  <transmission name="aileARD_tran">
    <type>transmission_interface/SimpleTransmission</type>
    <joint name="aileARD">
      <hardwareInterface>hardware_interface/EffortJointInterface</hardwareInterface>
    </joint>
    <actuator name="aileARD_moteur">
      <mechanicalReduction>1</mechanicalReduction>
      <hardwareInterface>hardware_interface/EffortJointInterface</hardwareInterface>
    </actuator>
  </transmission>
  <transmission name="epauleARD_tran">
    <type>transmission_interface/SimpleTransmission</type>
    <joint name="epauleARD">
      <hardwareInterface>hardware_interface/EffortJointInterface</hardwareInterface>
    </joint>
    <actuator name="epauleARD_moteur">
      <mechanicalReduction>1</mechanicalReduction>
      <hardwareInterface>hardware_interface/EffortJointInterface</hardwareInterface>
    </actuator>
  </transmission>
  <transmission name="coudeARD_tran">
    <type>transmission_interface/SimpleTransmission</type>
    <joint name="coudeARD">
      <hardwareInterface>hardware_interface/EffortJointInterface</hardwareInterface>
    </joint>
    <actuator name="coudeARD_moteur">
      <mechanicalReduction>1</mechanicalReduction>
      <hardwareInterface>hardware_interface/EffortJointInterface</hardwareInterface>
    </actuator>
  </transmission>
  <!--**************************************************************************************-->
  <!--**************************** TRANSMISSIONS ARRIERE-GAUCHES ***************************-->
  <!--**************************************************************************************-->
  <transmission name="aileARG_tran">
    <type>transmission_interface/SimpleTransmission</type>
    <joint name="aileARG">
      <hardwareInterface>hardware_interface/EffortJointInterface</hardwareInterface>
    </joint>
    <actuator name="aileARG_moteur">
      <mechanicalReduction>1</mechanicalReduction>
      <hardwareInterface>hardware_interface/EffortJointInterface</hardwareInterface>
    </actuator>
  </transmission>
  <transmission name="epauleARG_tran">
    <type>transmission_interface/SimpleTransmission</type>
    <joint name="epauleARG">
      <hardwareInterface>hardware_interface/EffortJointInterface</hardwareInterface>
    </joint>
    <actuator name="epauleARG_moteur">
      <mechanicalReduction>1</mechanicalReduction>
      <hardwareInterface>hardware_interface/EffortJointInterface</hardwareInterface>
    </actuator>
  </transmission>
  <transmission name="coudeARG_tran">
    <type>transmission_interface/SimpleTransmission</type>
    <joint name="coudeARG">
      <hardwareInterface>hardware_interface/EffortJointInterface</hardwareInterface>
    </joint>
    <actuator name="coudeARG_moteur">
      <mechanicalReduction>1</mechanicalReduction>
      <hardwareInterface>hardware_interface/EffortJointInterface</hardwareInterface>
    </actuator>
  </transmission>
</robot>

